<?xml version="1.0" encoding="utf-8"?>
<robot
  name="rm_65_b">
  <link
    name="base_link">
    <inertial>
      <origin
        xyz="-0.000433277303987328 -3.54664423471128E-05 0.0599427668933796"
        rpy="0 0 0" />
      <mass
        value="0.841070778135659" />
      <inertia
        ixx="0.0017261110801622"
        ixy="2.52746264980217E-06"
        ixz="-3.67690303614961E-05"
        iyy="0.00170987405835604"
        iyz="1.67996364994424E-06"
        izz="0.000904023422915791" />
    </inertial>
    <visual>
      <origin
        xyz="0 0 0"
        rpy="0 0 0" />
      <geometry>
        <mesh
          filename="package://rm_65_b/meshes/base_link.STL" />
      </geometry>
      <material
        name="">
        <color
          rgba="1 1 1 1" />
      </material>
    </visual>
    <collision>
      <origin
        xyz="0 0 0"
        rpy="0 0 0" />
      <geometry>
        <mesh
          filename="package://rm_65_b/meshes/base_link.STL" />
      </geometry>
    </collision>
  </link>
  <link
    name="Link1">
    <inertial>
      <origin
        xyz="1.2226305431569E-08 0.0211079974844683 -0.0251854220842269"
        rpy="0 0 0" />
      <mass
        value="0.593563443690403" />
      <inertia
        ixx="0.00126614120341847"
        ixy="-1.294980943835E-08"
        ixz="-9.80120923066996E-09"
        iyy="0.00118168178300364"
        iyz="-0.00021121727444415"
        izz="0.00056135241627747" />
    </inertial>
    <visual>
      <origin
        xyz="0 0 0"
        rpy="0 0 0" />
      <geometry>
        <mesh
          filename="package://rm_65_b/meshes/link1.STL" />
      </geometry>
      <material
        name="">
        <color
          rgba="1 1 1 1" />
      </material>
    </visual>
    <collision>
      <origin
        xyz="0 0 0"
        rpy="0 0 0" />
      <geometry>
        <mesh
          filename="package://rm_65_b/meshes/link1.STL" />
      </geometry>
    </collision>
  </link>
  <joint
    name="joint1"
    type="revolute">
    <origin
      xyz="0 0 0.2405"
      rpy="0 0 0" />
    <parent
      link="base_link" />
    <child
      link="Link1" />
    <axis
      xyz="0 0 1" />
    <limit
      lower="-3.1"
      upper="3.1"
      effort="60"
      velocity="3.14" />
  </joint>
  <link
    name="Link2">
    <inertial>
      <origin
        xyz="0.152256463426163 4.75383656106654E-07 -0.00620260383607792"
        rpy="0 0 0" />
      <mass
        value="0.864175046869043" />
      <inertia
        ixx="0.00089150298478414"
        ixy="-2.23268489334765E-08"
        ixz="0.00156246461035015"
        iyy="0.00733754343083901"
        iyz="6.28110889329165E-09"
        izz="0.00697869103915473" />
    </inertial>
    <visual>
      <origin
        xyz="0 0 0"
        rpy="0 0 0" />
      <geometry>
        <mesh
          filename="package://rm_65_b/meshes/link2.STL" />
      </geometry>
      <material
        name="">
        <color
          rgba="1 1 1 1" />
      </material>
    </visual>
    <collision>
      <origin
        xyz="0 0 0"
        rpy="0 0 0" />
      <geometry>
        <mesh
          filename="package://rm_65_b/meshes/link2.STL" />
      </geometry>
    </collision>
  </link>
  <joint
    name="joint2"
    type="revolute">
    <origin
      xyz="0 0 0"
      rpy="1.5708 -1.5708 0" />
    <parent
      link="Link1" />
    <child
      link="Link2" />
    <axis
      xyz="0 0 1" />
    <limit
      lower="-2.268"
      upper="2.268"
      effort="60"
      velocity="3.14" />
  </joint>
  <link
    name="Link3">
    <inertial>
      <origin
        xyz="5.05312670989961E-06 -0.0595925663694732 0.010569069212336"
        rpy="0 0 0" />
      <mass
        value="0.289633681624654" />
      <inertia
        ixx="0.00063737100450158"
        ixy="-7.05261293649751E-08"
        ixz="-3.86643272239426E-08"
        iyy="0.00015648388095025"
        iyz="-0.00014461035994916"
        izz="0.000614178164773085" />
    </inertial>
    <visual>
      <origin
        xyz="0 0 0"
        rpy="0 0 0" />
      <geometry>
        <mesh
          filename="package://rm_65_b/meshes/link3.STL" />
      </geometry>
      <material
        name="">
        <color
          rgba="1 1 1 1" />
      </material>
    </visual>
    <collision>
      <origin
        xyz="0 0 0"
        rpy="0 0 0" />
      <geometry>
        <mesh
          filename="package://rm_65_b/meshes/link3.STL" />
      </geometry>
    </collision>
  </link>
  <joint
    name="joint3"
    type="revolute">
    <origin
      xyz="0.256 0 0"
      rpy="0 0 1.5708" />
    <parent
      link="Link2" />
    <child
      link="Link3" />
    <axis
      xyz="0 0 1" />
    <limit
      lower="-2.355"
      upper="2.355"
      effort="30"
      velocity="3.92" />
  </joint>
  <link
    name="Link4">
    <inertial>
      <origin
        xyz="1.15516617405898E-06 -0.0180424468598241 -0.0215394748352687"
        rpy="0 0 0" />
      <mass
        value="0.239419768320061" />
      <inertia
        ixx="0.000285938919722783"
        ixy="3.07101359163101E-09"
        ixz="-2.21994118981953E-09"
        iyy="0.000262727540304212"
        iyz="4.4236583260078E-05"
        izz="0.000119888082791859" />
    </inertial>
    <visual>
      <origin
        xyz="0 0 0"
        rpy="0 0 0" />
      <geometry>
        <mesh
          filename="package://rm_65_b/meshes/link4.STL" />
      </geometry>
      <material
        name="">
        <color
          rgba="1 1 1 1" />
      </material>
    </visual>
    <collision>
      <origin
        xyz="0 0 0"
        rpy="0 0 0" />
      <geometry>
        <mesh
          filename="package://rm_65_b/meshes/link4.STL" />
      </geometry>
    </collision>
  </link>
  <joint
    name="joint4"
    type="revolute">
    <origin
      xyz="0 -0.21 0"
      rpy="1.5708 0 0" />
    <parent
      link="Link3" />
    <child
      link="Link4" />
    <axis
      xyz="0 0 1" />
    <limit
      lower="-3.1"
      upper="3.1"
      effort="10"
      velocity="3.92" />
  </joint>
  <link
    name="Link5">
    <inertial>
      <origin
        xyz="3.19794786262152E-06 -0.0593808368101458 0.00736804250989326"
        rpy="0 0 0" />
      <mass
        value="0.218799761431678" />
      <inertia
        ixx="0.000350540363914072"
        ixy="-3.41781619975602E-08"
        ixz="-1.77056457224373E-08"
        iyy="0.000104927867487581"
        iyz="-7.82431228461971E-05"
        izz="0.000334482418423629" />
    </inertial>
    <visual>
      <origin
        xyz="0 0 0"
        rpy="0 0 0" />
      <geometry>
        <mesh
          filename="package://rm_65_b/meshes/link5.STL" />
      </geometry>
      <material
        name="">
        <color
          rgba="1 1 1 1" />
      </material>
    </visual>
    <collision>
      <origin
        xyz="0 0 0"
        rpy="0 0 0" />
      <geometry>
        <mesh
          filename="package://rm_65_b/meshes/link5.STL" />
      </geometry>
    </collision>
  </link>
  <joint
    name="joint5"
    type="revolute">
    <origin
      xyz="0 0 0"
      rpy="-1.5708 0 0" />
    <parent
      link="Link4" />
    <child
      link="Link5" />
    <axis
      xyz="0 0 1" />
    <limit
      lower="-2.233"
      upper="2.233"
      effort="10"
      velocity="3.92" />
  </joint>
  <link
    name="Link6">
    <inertial>
      <origin
        xyz="0.000714234511756999 -0.000396718732824521 -0.0126723660946126"
        rpy="0 0 0" />
      <mass
        value="0.0649018034311231" />
      <inertia
        ixx="2.02766547502765E-05"
        ixy="-1.32505200276849E-06"
        ixz="-2.5845091522508E-08"
        iyy="1.87986725225022E-05"
        iyz="3.39471452125439E-09"
        izz="3.17885459163081E-05" />
    </inertial>
    <visual>
      <origin
        xyz="0 0 0"
        rpy="0 0 0" />
      <geometry>
        <mesh
          filename="package://rm_65_b/meshes/link6.STL" />
      </geometry>
      <material
        name="">
        <color
          rgba="1 1 1 1" />
      </material>
    </visual>
    <collision>
      <origin
        xyz="0 0 0"
        rpy="0 0 0" />
      <geometry>
        <mesh
          filename="package://rm_65_b/meshes/link6.STL" />
      </geometry>
    </collision>
  </link>
  <joint
    name="joint6"
    type="revolute">
    <origin
      xyz="0 -0.144 0"
      rpy="1.5708 0 0" />
    <parent
      link="Link5" />
    <child
      link="Link6" />
    <axis
      xyz="0 0 1" />
    <limit
      lower="-6.28"
      upper="6.28"
      effort="10"
      velocity="3.92" />
  </joint>
  <link
    name="4C2_baselink">
    <inertial>
      <origin
        xyz="1.5645E-05 -4.1838E-06 0.038"
        rpy="0 0 0" />
      <mass
        value="0.072633" />
      <inertia
        ixx="5.095E-05"
        ixy="-7.3167E-13"
        ixz="2.0229E-08"
        iyy="6.0883E-05"
        iyz="-4.5583E-09"
        izz="1.933E-05" />
    </inertial>
    <visual>
      <origin
        xyz="0 0 0"
        rpy="0 0 0" />
      <geometry>
        <mesh
          filename="package://rm_65_b/meshes/4C2_baselink.STL" />
      </geometry>
      <material
        name="">
        <color
          rgba="0.75294 0.75294 0.75294 1" />
      </material>
    </visual>
    <collision>
      <origin
        xyz="0 0 0"
        rpy="0 0 0" />
      <geometry>
        <mesh
          filename="package://rm_65_b/meshes/4C2_baselink.STL" />
      </geometry>
    </collision>
  </link>
  <link
    name="4C2_Link1">
    <inertial>
      <origin
        xyz="0.0087669 0.009 0.013992"
        rpy="0 0 0" />
      <mass
        value="0.0024292" />
      <inertia
        ixx="5.1061E-07"
        ixy="-8.6739E-19"
        ixz="-2.508E-07"
        iyy="5.7398E-07"
        iyz="-1.3667E-18"
        izz="2.6747E-07" />
    </inertial>
    <visual>
      <origin
        xyz="0 0 0"
        rpy="0 0 0" />
      <geometry>
        <mesh
          filename="package://rm_65_b/meshes/4C2_Link1.STL" />
      </geometry>
      <material
        name="">
        <color
          rgba="0.75294 0.75294 0.75294 1" />
      </material>
    </visual>
    <collision>
      <origin
        xyz="0 0 0"
        rpy="0 0 0" />
      <geometry>
        <mesh
          filename="package://rm_65_b/meshes/4C2_Link1.STL" />
      </geometry>
    </collision>
  </link>
  <joint
    name="4C2_Joint1"
    type="revolute">
    <origin
      xyz="-0.04 -0.009 0.079"
      rpy="0 0 0" />
    <parent
      link="4C2_baselink" />
    <child
      link="4C2_Link1" />
    <axis
      xyz="0 -1 0" />
    <limit
      lower="0"
      upper="0.82"
      effort="1"
      velocity="1" />

  </joint>
  <link
    name="4C2_Link5">
    <inertial>
      <origin
        xyz="0.011864 0.006 0.011367"
        rpy="0 0 0" />
      <mass
        value="0.0045068" />
      <inertia
        ixx="5.1288E-07"
        ixy="-9.8137E-14"
        ixz="-9.4703E-08"
        iyy="5.3203E-07"
        iyz="-6.212E-14"
        izz="2.009E-07" />
    </inertial>
    <visual>
      <origin
        xyz="0 0 0"
        rpy="0 0 0" />
      <geometry>
        <mesh
          filename="package://rm_65_b/meshes/4C2_Link5.STL" />
      </geometry>
      <material
        name="">
        <color
          rgba="0.75294 0.75294 0.75294 1" />
      </material>
    </visual>
    <collision>
      <origin
        xyz="0 0 0"
        rpy="0 0 0" />
      <geometry>
        <mesh
          filename="package://rm_65_b/meshes/4C2_Link5.STL" />
      </geometry>
    </collision>
  </link>
  <joint
    name="4C2_Joint5"
    type="revolute">
    <origin
      xyz="0.0223 0.003 0.035591"
      rpy="0 0 0" />
    <parent
      link="4C2_Link1" />
    <child
      link="4C2_Link5" />
    <axis
      xyz="0 1 0" />
    <limit
      lower="0"
      upper="0.82"
      effort="1"
      velocity="1" />
    <mimic joint="4C2_Joint1"/>
  </joint>
  <link
    name="4C2_Link2">
    <inertial>
      <origin
        xyz="0.0087435 0.009 0.013955"
        rpy="0 0 0" />
      <mass
        value="0.0038971" />
      <inertia
        ixx="5.6941E-07"
        ixy="-1.0711E-18"
        ixz="-2.6891E-07"
        iyy="6.2305E-07"
        iyz="-1.6845E-18"
        izz="3.0871E-07" />
    </inertial>
    <visual>
      <origin
        xyz="0 0 0"
        rpy="0 0 0" />
      <geometry>
        <mesh
          filename="package://rm_65_b/meshes/4C2_Link2.STL" />
      </geometry>
      <material
        name="">
        <color
          rgba="0.75294 0.75294 0.75294 1" />
      </material>
    </visual>
    <collision>
      <origin
        xyz="0 0 0"
        rpy="0 0 0" />
      <geometry>
        <mesh
          filename="package://rm_65_b/meshes/4C2_Link2.STL" />
      </geometry>
    </collision>
  </link>
  <joint
    name="4C2_Joint2"
    type="revolute">
    <origin
      xyz="-0.03 -0.009 0.081"
      rpy="0 0 0" />
    <parent
      link="4C2_baselink" />
    <child
      link="4C2_Link2" />
    <axis
      xyz="0 -1 0" />
    <limit
      lower="0"
      upper="0.82"
      effort="1"
      velocity="1" />
    <mimic joint="4C2_Joint1"/>
  </joint>
  <link
    name="4C2_Link3">
    <inertial>
      <origin
        xyz="-0.0087435 0.009 0.013955"
        rpy="0 0 0" />
      <mass
        value="0.0038971" />
      <inertia
        ixx="5.6941E-07"
        ixy="1.0666E-18"
        ixz="2.6891E-07"
        iyy="6.2305E-07"
        iyz="-1.8084E-18"
        izz="3.0871E-07" />
    </inertial>
    <visual>
      <origin
        xyz="0 0 0"
        rpy="0 0 0" />
      <geometry>
        <mesh
          filename="package://rm_65_b/meshes/4C2_Link3.STL" />
      </geometry>
      <material
        name="">
        <color
          rgba="0.75294 0.75294 0.75294 1" />
      </material>
    </visual>
    <collision>
      <origin
        xyz="0 0 0"
        rpy="0 0 0" />
      <geometry>
        <mesh
          filename="package://rm_65_b/meshes/4C2_Link3.STL" />
      </geometry>
    </collision>
  </link>
  <joint
    name="4C2_Joint3"
    type="revolute">
    <origin
      xyz="0.03 -0.009 0.081"
      rpy="0 0 0" />
    <parent
      link="4C2_baselink" />
    <child
      link="4C2_Link3" />
    <axis
      xyz="0 -1 0" />
    <limit
      lower="-0.82"
      upper="0"
      effort="1"
      velocity="1" />
    <mimic joint="4C2_Joint1" multiplier="-1"  offset="0"/>
  </joint>
  <link
    name="4C2_Link4">
    <inertial>
      <origin
        xyz="-0.0087669 0.009 0.013992"
        rpy="0 0 0" />
      <mass
        value="0.0024292" />
      <inertia
        ixx="5.1061E-07"
        ixy="-9.5279E-19"
        ixz="2.508E-07"
        iyy="5.7398E-07"
        iyz="7.6863E-19"
        izz="2.6747E-07" />
    </inertial>
    <visual>
      <origin
        xyz="0 0 0"
        rpy="0 0 0" />
      <geometry>
        <mesh
          filename="package://rm_65_b/meshes/4C2_Link4.STL" />
      </geometry>
      <material
        name="">
        <color
          rgba="0.75294 0.75294 0.75294 1" />
      </material>
    </visual>
    <collision>
      <origin
        xyz="0 0 0"
        rpy="0 0 0" />
      <geometry>
        <mesh
          filename="package://rm_65_b/meshes/4C2_Link4.STL" />
      </geometry>
    </collision>
  </link>
  <joint
    name="4C2_Joint4"
    type="revolute">
    <origin
      xyz="0.04 -0.009 0.079"
      rpy="0 0 0" />
    <parent
      link="4C2_baselink" />
    <child
      link="4C2_Link4" />
    <axis
      xyz="0 -1 0" />
    <limit
      lower="-0.82"
      upper="0"
      effort="1"
      velocity="1" />
    <mimic joint="4C2_Joint1" multiplier="-1"  offset="0"/>
  </joint>
  <link
    name="4C2_Link6">
    <inertial>
      <origin
        xyz="-0.011864 0.006 0.011367"
        rpy="0 0 0" />
      <mass
        value="0.0045068" />
      <inertia
        ixx="5.1288E-07"
        ixy="-9.8137E-14"
        ixz="9.4703E-08"
        iyy="5.3203E-07"
        iyz="6.2119E-14"
        izz="2.009E-07" />
    </inertial>
    <visual>
      <origin
        xyz="0 0 0"
        rpy="0 0 0" />
      <geometry>
        <mesh
          filename="package://rm_65_b/meshes/4C2_Link6.STL" />
      </geometry>
      <material
        name="">
        <color
          rgba="0.75294 0.75294 0.75294 1" />
      </material>
    </visual>
    <collision>
      <origin
        xyz="0 0 0"
        rpy="0 0 0" />
      <geometry>
        <mesh
          filename="package://rm_65_b/meshes/4C2_Link6.STL" />
      </geometry>
    </collision>
  </link>
  <joint
    name="4C2_Joint6"
    type="revolute">
    <origin
      xyz="-0.0223 0.003 0.035591"
      rpy="0 0 0" />
    <parent
      link="4C2_Link4" />
    <child
      link="4C2_Link6" />
    <axis
      xyz="0 -1 0" />
    <limit
      lower="0"
      upper="0.82"
      effort="1"
      velocity="1" />
    <mimic joint="4C2_Joint1"/>
  </joint>
  <joint
    name="gripper_base_link"
    type="fixed">
    <orgin
      xyz="0.011 0.0 0.057"
      rpy="0.0 1.5708 0.0"/>
    <parent
      link="fixed_plate_link" />
    <child
      link="4C2_baselink" />
    <axis
      xyz="0 0 1" />
  </joint>
  <link
    name="fixed_plate_link">
    <inertial>
      <origin
        xyz="0.045819 6.35930000024774E-09 0.0040461"
        rpy="0 0 0" />
      <mass
        value="0.13853" />
      <inertia
        ixx="4.2971E-05"
        ixy="4.08909999999764E-11"
        ixz="3.8593E-07"
        iyy="0.00023364"
        iyz="1.36420000025386E-11"
        izz="0.0002751" />
    </inertial>
    <visual>
      <origin
        xyz="0 0 0"
        rpy="1.5707963267949 0 0" />
      <geometry>
        <mesh
          filename="package://rm_65_b/meshes/fixed_plate.STL" />
      </geometry>
      <material
        name="">
        <color
          rgba="0.89804 0.91765 0.92941 1" />
        <texture
          filename="package://rm_65_b/textures/" />
      </material>
    </visual>
    <collision>
      <origin
        xyz="0 0 0"
        rpy="1.5707963267949 0 0" />
      <geometry>
        <mesh
          filename="package://rm_65_b/meshes/fixed_plate.STL" />
      </geometry>
    </collision>
  </link>
  <joint
    name="fixed_plate"
    type="fixed">
    <origin
      xyz="0 0 0.057"
      rpy="3.1415 0 0" />
    <parent
      link="Link6" />
    <child
      link="fixed_plate_link" />
    <axis
      xyz="0 0 1" />
  </joint>
</robot>
